2025-07-19T12:36:48.457147+00:00 | init | Log file created\n---\n2025-07-19T12:40:00.632366+00:00 | root.py main() failure | NotImplementedError('Main agent not implemented yet')
Traceback (most recent call last):
  File "F:\repos\LLM-test\root.py", line 15, in main
    raise NotImplementedError("Main agent not implemented yet")
NotImplementedError: Main agent not implemented yet

---
2025-07-19T12:42:44.173056+00:00 | root.py main() failure | NotImplementedError('Main agent not implemented yet')
Traceback (most recent call last):
  File "F:\repos\LLM-test\root.py", line 15, in main
    raise NotImplementedError("Main agent not implemented yet")
NotImplementedError: Main agent not implemented yet

---
2025-07-19T12:42:44.992895+00:00 | read_codebase: unable to read F:\repos\LLM-test\requirements.txt | UnicodeDecodeError('utf-8', b'\xff\xfea\x00n\x00n\x00o\x00t\x00a\x00t\x00e\x00d\x00-\x00t\x00y\x00p\x00e\x00s\x00=\x00=\x000\x00.\x007\x00.\x000\x00\r\x00\n\x00a\x00n\x00y\x00i\x00o\x00=\x00=\x004\x00.\x009\x00.\x000\x00\r\x00\n\x00c\x00e\x00r\x00t\x00i\x00f\x00i\x00=\x00=\x002\x000\x002\x005\x00.\x007\x00.\x001\x004\x00\r\x00\n\x00c\x00o\x00l\x00o\x00r\x00a\x00m\x00a\x00=\x00=\x000\x00.\x004\x00.\x006\x00\r\x00\n\x00d\x00i\x00s\x00t\x00r\x00o\x00=\x00=\x001\x00.\x009\x00.\x000\x00\r\x00\n\x00d\x00o\x00t\x00e\x00n\x00v\x00=\x00=\x000\x00.\x009\x00.\x009\x00\r\x00\n\x00h\x001\x001\x00=\x00=\x000\x00.\x001\x006\x00.\x000\x00\r\x00\n\x00h\x00t\x00t\x00p\x00c\x00o\x00r\x00e\x00=\x00=\x001\x00.\x000\x00.\x009\x00\r\x00\n\x00h\x00t\x00t\x00p\x00x\x00=\x00=\x000\x00.\x002\x008\x00.\x001\x00\r\x00\n\x00i\x00d\x00n\x00a\x00=\x00=\x003\x00.\x001\x000\x00\r\x00\n\x00j\x00i\x00t\x00e\x00r\x00=\x00=\x000\x00.\x001\x000\x00.\x000\x00\r\x00\n\x00o\x00p\x00e\x00n\x00a\x00i\x00=\x00=\x001\x00.\x009\x007\x00.\x000\x00\r\x00\n\x00p\x00y\x00d\x00a\x00n\x00t\x00i\x00c\x00=\x00=\x002\x00.\x001\x001\x00.\x007\x00\r\x00\n\x00p\x00y\x00d\x00a\x00n\x00t\x00i\x00c\x00_\x00c\x00o\x00r\x00e\x00=\x00=\x002\x00.\x003\x003\x00.\x002\x00\r\x00\n\x00p\x00y\x00t\x00h\x00o\x00n\x00-\x00d\x00o\x00t\x00e\x00n\x00v\x00=\x00=\x001\x00.\x001\x00.\x001\x00\r\x00\n\x00s\x00n\x00i\x00f\x00f\x00i\x00o\x00=\x00=\x001\x00.\x003\x00.\x001\x00\r\x00\n\x00t\x00q\x00d\x00m\x00=\x00=\x004\x00.\x006\x007\x00.\x001\x00\r\x00\n\x00t\x00y\x00p\x00i\x00n\x00g\x00-\x00i\x00n\x00s\x00p\x00e\x00c\x00t\x00i\x00o\x00n\x00=\x00=\x000\x00.\x004\x00.\x001\x00\r\x00\n\x00t\x00y\x00p\x00i\x00n\x00g\x00_\x00e\x00x\x00t\x00e\x00n\x00s\x00i\x00o\x00n\x00s\x00=\x00=\x004\x00.\x001\x004\x00.\x001\x00\r\x00\n\x00', 0, 1, 'invalid start byte')
Traceback (most recent call last):
  File "F:\repos\LLM-test\root.py", line 15, in main
    raise NotImplementedError("Main agent not implemented yet")
NotImplementedError: Main agent not implemented yet

During handling of the above exception, another exception occurred:

Traceback (most recent call last):
  File "F:\repos\LLM-test\fallback.py", line 63, in read_codebase
    files[str(path.relative_to(root))] = path.read_text(encoding="utf-8")
                                         ^^^^^^^^^^^^^^^^^^^^^^^^^^^^^^^^
  File "C:\Python312\Lib\pathlib.py", line 1028, in read_text
    return f.read()
           ^^^^^^^^
  File "<frozen codecs>", line 322, in decode
UnicodeDecodeError: 'utf-8' codec can't decode byte 0xff in position 0: invalid start byte

---
2025-07-19T12:43:53.360673+00:00 | helpers.read_codebase: cannot read F:\repos\LLM-test\requirements.txt | UnicodeDecodeError('utf-8', b'\xff\xfea\x00n\x00n\x00o\x00t\x00a\x00t\x00e\x00d\x00-\x00t\x00y\x00p\x00e\x00s\x00=\x00=\x000\x00.\x007\x00.\x000\x00\r\x00\n\x00a\x00n\x00y\x00i\x00o\x00=\x00=\x004\x00.\x009\x00.\x000\x00\r\x00\n\x00c\x00e\x00r\x00t\x00i\x00f\x00i\x00=\x00=\x002\x000\x002\x005\x00.\x007\x00.\x001\x004\x00\r\x00\n\x00c\x00o\x00l\x00o\x00r\x00a\x00m\x00a\x00=\x00=\x000\x00.\x004\x00.\x006\x00\r\x00\n\x00d\x00i\x00s\x00t\x00r\x00o\x00=\x00=\x001\x00.\x009\x00.\x000\x00\r\x00\n\x00d\x00o\x00t\x00e\x00n\x00v\x00=\x00=\x000\x00.\x009\x00.\x009\x00\r\x00\n\x00h\x001\x001\x00=\x00=\x000\x00.\x001\x006\x00.\x000\x00\r\x00\n\x00h\x00t\x00t\x00p\x00c\x00o\x00r\x00e\x00=\x00=\x001\x00.\x000\x00.\x009\x00\r\x00\n\x00h\x00t\x00t\x00p\x00x\x00=\x00=\x000\x00.\x002\x008\x00.\x001\x00\r\x00\n\x00i\x00d\x00n\x00a\x00=\x00=\x003\x00.\x001\x000\x00\r\x00\n\x00j\x00i\x00t\x00e\x00r\x00=\x00=\x000\x00.\x001\x000\x00.\x000\x00\r\x00\n\x00o\x00p\x00e\x00n\x00a\x00i\x00=\x00=\x001\x00.\x009\x007\x00.\x000\x00\r\x00\n\x00p\x00y\x00d\x00a\x00n\x00t\x00i\x00c\x00=\x00=\x002\x00.\x001\x001\x00.\x007\x00\r\x00\n\x00p\x00y\x00d\x00a\x00n\x00t\x00i\x00c\x00_\x00c\x00o\x00r\x00e\x00=\x00=\x002\x00.\x003\x003\x00.\x002\x00\r\x00\n\x00p\x00y\x00t\x00h\x00o\x00n\x00-\x00d\x00o\x00t\x00e\x00n\x00v\x00=\x00=\x001\x00.\x001\x00.\x001\x00\r\x00\n\x00s\x00n\x00i\x00f\x00f\x00i\x00o\x00=\x00=\x001\x00.\x003\x00.\x001\x00\r\x00\n\x00t\x00q\x00d\x00m\x00=\x00=\x004\x00.\x006\x007\x00.\x001\x00\r\x00\n\x00t\x00y\x00p\x00i\x00n\x00g\x00-\x00i\x00n\x00s\x00p\x00e\x00c\x00t\x00i\x00o\x00n\x00=\x00=\x000\x00.\x004\x00.\x001\x00\r\x00\n\x00t\x00y\x00p\x00i\x00n\x00g\x00_\x00e\x00x\x00t\x00e\x00n\x00s\x00i\x00o\x00n\x00s\x00=\x00=\x004\x00.\x001\x004\x00.\x001\x00\r\x00\n\x00', 0, 1, 'invalid start byte')
Traceback (most recent call last):
  File "F:\repos\LLM-test\helpers.py", line 45, in read_codebase
    files[str(path.relative_to(root))] = path.read_text(encoding="utf-8")
                                         ^^^^^^^^^^^^^^^^^^^^^^^^^^^^^^^^
  File "C:\Python312\Lib\pathlib.py", line 1028, in read_text
    return f.read()
           ^^^^^^^^
  File "<frozen codecs>", line 322, in decode
UnicodeDecodeError: 'utf-8' codec can't decode byte 0xff in position 0: invalid start byte

---
2025-07-19T12:43:54.920597+00:00 | planner_agent._call_llm | OpenAIError('Missing credentials. Please pass one of `api_key`, `azure_ad_token`, `azure_ad_token_provider`, or the `AZURE_OPENAI_API_KEY` or `AZURE_OPENAI_AD_TOKEN` environment variables.')
Traceback (most recent call last):
  File "F:\repos\LLM-test\agents\planner_agent.py", line 12, in _call_llm
    client = AzureOpenAI(
             ^^^^^^^^^^^^
  File "F:\repos\LLM-test\.venv\Lib\site-packages\openai\lib\azure.py", line 199, in __init__
    raise OpenAIError(
openai.OpenAIError: Missing credentials. Please pass one of `api_key`, `azure_ad_token`, `azure_ad_token_provider`, or the `AZURE_OPENAI_API_KEY` or `AZURE_OPENAI_AD_TOKEN` environment variables.

---
2025-07-19T12:43:54.921599+00:00 | orchestrator main() failure | OpenAIError('Missing credentials. Please pass one of `api_key`, `azure_ad_token`, `azure_ad_token_provider`, or the `AZURE_OPENAI_API_KEY` or `AZURE_OPENAI_AD_TOKEN` environment variables.')
Traceback (most recent call last):
  File "F:\repos\LLM-test\root.py", line 14, in main
    planner_agent.run(project_root)
  File "F:\repos\LLM-test\agents\planner_agent.py", line 54, in run
    code_response = _call_llm(system_prompt, user_prompt)
                    ^^^^^^^^^^^^^^^^^^^^^^^^^^^^^^^^^^^^^
  File "F:\repos\LLM-test\agents\planner_agent.py", line 12, in _call_llm
    client = AzureOpenAI(
             ^^^^^^^^^^^^
  File "F:\repos\LLM-test\.venv\Lib\site-packages\openai\lib\azure.py", line 199, in __init__
    raise OpenAIError(
openai.OpenAIError: Missing credentials. Please pass one of `api_key`, `azure_ad_token`, `azure_ad_token_provider`, or the `AZURE_OPENAI_API_KEY` or `AZURE_OPENAI_AD_TOKEN` environment variables.

---
2025-07-19T12:43:54.933610+00:00 | read_codebase: unable to read F:\repos\LLM-test\requirements.txt | UnicodeDecodeError('utf-8', b'\xff\xfea\x00n\x00n\x00o\x00t\x00a\x00t\x00e\x00d\x00-\x00t\x00y\x00p\x00e\x00s\x00=\x00=\x000\x00.\x007\x00.\x000\x00\r\x00\n\x00a\x00n\x00y\x00i\x00o\x00=\x00=\x004\x00.\x009\x00.\x000\x00\r\x00\n\x00c\x00e\x00r\x00t\x00i\x00f\x00i\x00=\x00=\x002\x000\x002\x005\x00.\x007\x00.\x001\x004\x00\r\x00\n\x00c\x00o\x00l\x00o\x00r\x00a\x00m\x00a\x00=\x00=\x000\x00.\x004\x00.\x006\x00\r\x00\n\x00d\x00i\x00s\x00t\x00r\x00o\x00=\x00=\x001\x00.\x009\x00.\x000\x00\r\x00\n\x00d\x00o\x00t\x00e\x00n\x00v\x00=\x00=\x000\x00.\x009\x00.\x009\x00\r\x00\n\x00h\x001\x001\x00=\x00=\x000\x00.\x001\x006\x00.\x000\x00\r\x00\n\x00h\x00t\x00t\x00p\x00c\x00o\x00r\x00e\x00=\x00=\x001\x00.\x000\x00.\x009\x00\r\x00\n\x00h\x00t\x00t\x00p\x00x\x00=\x00=\x000\x00.\x002\x008\x00.\x001\x00\r\x00\n\x00i\x00d\x00n\x00a\x00=\x00=\x003\x00.\x001\x000\x00\r\x00\n\x00j\x00i\x00t\x00e\x00r\x00=\x00=\x000\x00.\x001\x000\x00.\x000\x00\r\x00\n\x00o\x00p\x00e\x00n\x00a\x00i\x00=\x00=\x001\x00.\x009\x007\x00.\x000\x00\r\x00\n\x00p\x00y\x00d\x00a\x00n\x00t\x00i\x00c\x00=\x00=\x002\x00.\x001\x001\x00.\x007\x00\r\x00\n\x00p\x00y\x00d\x00a\x00n\x00t\x00i\x00c\x00_\x00c\x00o\x00r\x00e\x00=\x00=\x002\x00.\x003\x003\x00.\x002\x00\r\x00\n\x00p\x00y\x00t\x00h\x00o\x00n\x00-\x00d\x00o\x00t\x00e\x00n\x00v\x00=\x00=\x001\x00.\x001\x00.\x001\x00\r\x00\n\x00s\x00n\x00i\x00f\x00f\x00i\x00o\x00=\x00=\x001\x00.\x003\x00.\x001\x00\r\x00\n\x00t\x00q\x00d\x00m\x00=\x00=\x004\x00.\x006\x007\x00.\x001\x00\r\x00\n\x00t\x00y\x00p\x00i\x00n\x00g\x00-\x00i\x00n\x00s\x00p\x00e\x00c\x00t\x00i\x00o\x00n\x00=\x00=\x000\x00.\x004\x00.\x001\x00\r\x00\n\x00t\x00y\x00p\x00i\x00n\x00g\x00_\x00e\x00x\x00t\x00e\x00n\x00s\x00i\x00o\x00n\x00s\x00=\x00=\x004\x00.\x001\x004\x00.\x001\x00\r\x00\n\x00', 0, 1, 'invalid start byte')
Traceback (most recent call last):
  File "F:\repos\LLM-test\root.py", line 14, in main
    planner_agent.run(project_root)
  File "F:\repos\LLM-test\agents\planner_agent.py", line 54, in run
    code_response = _call_llm(system_prompt, user_prompt)
                    ^^^^^^^^^^^^^^^^^^^^^^^^^^^^^^^^^^^^^
  File "F:\repos\LLM-test\agents\planner_agent.py", line 12, in _call_llm
    client = AzureOpenAI(
             ^^^^^^^^^^^^
  File "F:\repos\LLM-test\.venv\Lib\site-packages\openai\lib\azure.py", line 199, in __init__
    raise OpenAIError(
openai.OpenAIError: Missing credentials. Please pass one of `api_key`, `azure_ad_token`, `azure_ad_token_provider`, or the `AZURE_OPENAI_API_KEY` or `AZURE_OPENAI_AD_TOKEN` environment variables.

During handling of the above exception, another exception occurred:

Traceback (most recent call last):
  File "F:\repos\LLM-test\fallback.py", line 63, in read_codebase
    files[str(path.relative_to(root))] = path.read_text(encoding="utf-8")
                                         ^^^^^^^^^^^^^^^^^^^^^^^^^^^^^^^^
  File "C:\Python312\Lib\pathlib.py", line 1028, in read_text
    return f.read()
           ^^^^^^^^
  File "<frozen codecs>", line 322, in decode
UnicodeDecodeError: 'utf-8' codec can't decode byte 0xff in position 0: invalid start byte

---
2025-07-19T12:45:15.005655+00:00 | helpers.read_codebase: cannot read F:\repos\LLM-test\requirements.txt | UnicodeDecodeError('utf-8', b'\xff\xfea\x00n\x00n\x00o\x00t\x00a\x00t\x00e\x00d\x00-\x00t\x00y\x00p\x00e\x00s\x00=\x00=\x000\x00.\x007\x00.\x000\x00\r\x00\n\x00a\x00n\x00y\x00i\x00o\x00=\x00=\x004\x00.\x009\x00.\x000\x00\r\x00\n\x00c\x00e\x00r\x00t\x00i\x00f\x00i\x00=\x00=\x002\x000\x002\x005\x00.\x007\x00.\x001\x004\x00\r\x00\n\x00c\x00o\x00l\x00o\x00r\x00a\x00m\x00a\x00=\x00=\x000\x00.\x004\x00.\x006\x00\r\x00\n\x00d\x00i\x00s\x00t\x00r\x00o\x00=\x00=\x001\x00.\x009\x00.\x000\x00\r\x00\n\x00d\x00o\x00t\x00e\x00n\x00v\x00=\x00=\x000\x00.\x009\x00.\x009\x00\r\x00\n\x00h\x001\x001\x00=\x00=\x000\x00.\x001\x006\x00.\x000\x00\r\x00\n\x00h\x00t\x00t\x00p\x00c\x00o\x00r\x00e\x00=\x00=\x001\x00.\x000\x00.\x009\x00\r\x00\n\x00h\x00t\x00t\x00p\x00x\x00=\x00=\x000\x00.\x002\x008\x00.\x001\x00\r\x00\n\x00i\x00d\x00n\x00a\x00=\x00=\x003\x00.\x001\x000\x00\r\x00\n\x00j\x00i\x00t\x00e\x00r\x00=\x00=\x000\x00.\x001\x000\x00.\x000\x00\r\x00\n\x00o\x00p\x00e\x00n\x00a\x00i\x00=\x00=\x001\x00.\x009\x007\x00.\x000\x00\r\x00\n\x00p\x00y\x00d\x00a\x00n\x00t\x00i\x00c\x00=\x00=\x002\x00.\x001\x001\x00.\x007\x00\r\x00\n\x00p\x00y\x00d\x00a\x00n\x00t\x00i\x00c\x00_\x00c\x00o\x00r\x00e\x00=\x00=\x002\x00.\x003\x003\x00.\x002\x00\r\x00\n\x00p\x00y\x00t\x00h\x00o\x00n\x00-\x00d\x00o\x00t\x00e\x00n\x00v\x00=\x00=\x001\x00.\x001\x00.\x001\x00\r\x00\n\x00s\x00n\x00i\x00f\x00f\x00i\x00o\x00=\x00=\x001\x00.\x003\x00.\x001\x00\r\x00\n\x00t\x00q\x00d\x00m\x00=\x00=\x004\x00.\x006\x007\x00.\x001\x00\r\x00\n\x00t\x00y\x00p\x00i\x00n\x00g\x00-\x00i\x00n\x00s\x00p\x00e\x00c\x00t\x00i\x00o\x00n\x00=\x00=\x000\x00.\x004\x00.\x001\x00\r\x00\n\x00t\x00y\x00p\x00i\x00n\x00g\x00_\x00e\x00x\x00t\x00e\x00n\x00s\x00i\x00o\x00n\x00s\x00=\x00=\x004\x00.\x001\x004\x00.\x001\x00\r\x00\n\x00', 0, 1, 'invalid start byte')
Traceback (most recent call last):
  File "F:\repos\LLM-test\helpers.py", line 45, in read_codebase
    files[str(path.relative_to(root))] = path.read_text(encoding="utf-8")
                                         ^^^^^^^^^^^^^^^^^^^^^^^^^^^^^^^^
  File "C:\Python312\Lib\pathlib.py", line 1028, in read_text
    return f.read()
           ^^^^^^^^
  File "<frozen codecs>", line 322, in decode
UnicodeDecodeError: 'utf-8' codec can't decode byte 0xff in position 0: invalid start byte

---
2025-07-19T12:45:16.552733+00:00 | helpers.read_codebase: cannot read F:\repos\LLM-test\requirements.txt | UnicodeDecodeError('utf-8', b'\xff\xfea\x00n\x00n\x00o\x00t\x00a\x00t\x00e\x00d\x00-\x00t\x00y\x00p\x00e\x00s\x00=\x00=\x000\x00.\x007\x00.\x000\x00\r\x00\n\x00a\x00n\x00y\x00i\x00o\x00=\x00=\x004\x00.\x009\x00.\x000\x00\r\x00\n\x00c\x00e\x00r\x00t\x00i\x00f\x00i\x00=\x00=\x002\x000\x002\x005\x00.\x007\x00.\x001\x004\x00\r\x00\n\x00c\x00o\x00l\x00o\x00r\x00a\x00m\x00a\x00=\x00=\x000\x00.\x004\x00.\x006\x00\r\x00\n\x00d\x00i\x00s\x00t\x00r\x00o\x00=\x00=\x001\x00.\x009\x00.\x000\x00\r\x00\n\x00d\x00o\x00t\x00e\x00n\x00v\x00=\x00=\x000\x00.\x009\x00.\x009\x00\r\x00\n\x00h\x001\x001\x00=\x00=\x000\x00.\x001\x006\x00.\x000\x00\r\x00\n\x00h\x00t\x00t\x00p\x00c\x00o\x00r\x00e\x00=\x00=\x001\x00.\x000\x00.\x009\x00\r\x00\n\x00h\x00t\x00t\x00p\x00x\x00=\x00=\x000\x00.\x002\x008\x00.\x001\x00\r\x00\n\x00i\x00d\x00n\x00a\x00=\x00=\x003\x00.\x001\x000\x00\r\x00\n\x00j\x00i\x00t\x00e\x00r\x00=\x00=\x000\x00.\x001\x000\x00.\x000\x00\r\x00\n\x00o\x00p\x00e\x00n\x00a\x00i\x00=\x00=\x001\x00.\x009\x007\x00.\x000\x00\r\x00\n\x00p\x00y\x00d\x00a\x00n\x00t\x00i\x00c\x00=\x00=\x002\x00.\x001\x001\x00.\x007\x00\r\x00\n\x00p\x00y\x00d\x00a\x00n\x00t\x00i\x00c\x00_\x00c\x00o\x00r\x00e\x00=\x00=\x002\x00.\x003\x003\x00.\x002\x00\r\x00\n\x00p\x00y\x00t\x00h\x00o\x00n\x00-\x00d\x00o\x00t\x00e\x00n\x00v\x00=\x00=\x001\x00.\x001\x00.\x001\x00\r\x00\n\x00s\x00n\x00i\x00f\x00f\x00i\x00o\x00=\x00=\x001\x00.\x003\x00.\x001\x00\r\x00\n\x00t\x00q\x00d\x00m\x00=\x00=\x004\x00.\x006\x007\x00.\x001\x00\r\x00\n\x00t\x00y\x00p\x00i\x00n\x00g\x00-\x00i\x00n\x00s\x00p\x00e\x00c\x00t\x00i\x00o\x00n\x00=\x00=\x000\x00.\x004\x00.\x001\x00\r\x00\n\x00t\x00y\x00p\x00i\x00n\x00g\x00_\x00e\x00x\x00t\x00e\x00n\x00s\x00i\x00o\x00n\x00s\x00=\x00=\x004\x00.\x001\x004\x00.\x001\x00\r\x00\n\x00', 0, 1, 'invalid start byte')
Traceback (most recent call last):
  File "F:\repos\LLM-test\helpers.py", line 45, in read_codebase
    files[str(path.relative_to(root))] = path.read_text(encoding="utf-8")
                                         ^^^^^^^^^^^^^^^^^^^^^^^^^^^^^^^^
  File "C:\Python312\Lib\pathlib.py", line 1028, in read_text
    return f.read()
           ^^^^^^^^
  File "<frozen codecs>", line 322, in decode
UnicodeDecodeError: 'utf-8' codec can't decode byte 0xff in position 0: invalid start byte

---
